<html>
    <head>
        <body>
            <script>
                /*
                If the finally block returns a value, this value becomes the return value 
                of the entire try-catch-finally production, regardless of any return statements 
                in the try and catch blocks. This includes exceptions thrown inside of the catch block:
                */
                var x=(function() {
                    try {
                        try {
                            throw new Error('oops');
                            return 1; //doesn't work
                        }
                        catch (ex) {
                            console.error('inner', ex.message);
                            throw ex;
                            return 2; //doesn't work if there is a return in the finally
                        }
                        finally {
                            console.log('finally');
                            return 3; //ONLY ONE WORKING
                        }
                    }
                    catch (ex) {
                        console.error('outer', ex.message);
                        return 4;
                    }
                })();


                console.log("XXXXXXX", x);

                // Output:
                // "inner" "oops"
                // "finally"
                //The outer "oops" is not thrown because of the return in the finally block. The same would apply to any value returned from the catch block.

            </script>
        </body>
    </head>
</html>